[2025-10-01T22:15:58.108+0000] {local_task_job_runner.py:120} INFO - ::group::Pre task execution logs
[2025-10-01T22:15:58.119+0000] {taskinstance.py:2076} INFO - Dependencies all met for dep_context=non-requeueable deps ti=<TaskInstance: CountryCaptial_v1.load manual__2025-10-01T22:15:53.779539+00:00 [queued]>
[2025-10-01T22:15:58.122+0000] {taskinstance.py:2076} INFO - Dependencies all met for dep_context=requeueable deps ti=<TaskInstance: CountryCaptial_v1.load manual__2025-10-01T22:15:53.779539+00:00 [queued]>
[2025-10-01T22:15:58.122+0000] {taskinstance.py:2306} INFO - Starting attempt 1 of 1
[2025-10-01T22:15:58.128+0000] {taskinstance.py:2330} INFO - Executing <Task(_PythonDecoratedOperator): load> on 2025-10-01 22:15:53.779539+00:00
[2025-10-01T22:15:58.132+0000] {warnings.py:112} WARNING - /home/***/.local/lib/python3.12/site-packages/***/task/task_runner/standard_task_runner.py:62: DeprecationWarning: This process (pid=6461) is multi-threaded, use of fork() may lead to deadlocks in the child.
  pid = os.fork()

[2025-10-01T22:15:58.133+0000] {standard_task_runner.py:64} INFO - Started process 6465 to run task
[2025-10-01T22:15:58.133+0000] {standard_task_runner.py:90} INFO - Running: ['***', 'tasks', 'run', 'CountryCaptial_v1', 'load', 'manual__2025-10-01T22:15:53.779539+00:00', '--job-id', '493', '--raw', '--subdir', 'DAGS_FOLDER/country_capital_to_snowflake_v1.py', '--cfg-path', '/tmp/tmpsxwcoclv']
[2025-10-01T22:15:58.134+0000] {standard_task_runner.py:91} INFO - Job 493: Subtask load
[2025-10-01T22:15:58.154+0000] {task_command.py:426} INFO - Running <TaskInstance: CountryCaptial_v1.load manual__2025-10-01T22:15:53.779539+00:00 [running]> on host 11e1994bdecf
[2025-10-01T22:15:58.189+0000] {taskinstance.py:2648} INFO - Exporting env vars: AIRFLOW_CTX_DAG_OWNER='***' AIRFLOW_CTX_DAG_ID='CountryCaptial_v1' AIRFLOW_CTX_TASK_ID='load' AIRFLOW_CTX_EXECUTION_DATE='2025-10-01T22:15:53.779539+00:00' AIRFLOW_CTX_TRY_NUMBER='1' AIRFLOW_CTX_DAG_RUN_ID='manual__2025-10-01T22:15:53.779539+00:00'
[2025-10-01T22:15:58.190+0000] {taskinstance.py:430} INFO - ::endgroup::
[2025-10-01T22:15:58.199+0000] {connection.py:408} INFO - Snowflake Connector for Python Version: 3.11.0, Python Version: 3.12.4, Platform: Linux-6.10.14-linuxkit-aarch64-with-glibc2.36
[2025-10-01T22:15:58.199+0000] {connection.py:1258} INFO - This connection is in OCSP Fail Open Mode. TLS Certificates would be checked for validity and revocation status. Any other Certificate Revocation related exceptions or OCSP Responder failures would be disregarded in favor of connectivity.
[2025-10-01T22:15:58.432+0000] {taskinstance.py:441} INFO - ::group::Post task execution logs
[2025-10-01T22:15:58.432+0000] {taskinstance.py:2905} ERROR - Task failed with exception
Traceback (most recent call last):
  File "/home/airflow/.local/lib/python3.12/site-packages/airflow/models/taskinstance.py", line 465, in _execute_task
    result = _execute_callable(context=context, **execute_callable_kwargs)
             ^^^^^^^^^^^^^^^^^^^^^^^^^^^^^^^^^^^^^^^^^^^^^^^^^^^^^^^^^^^^^
  File "/home/airflow/.local/lib/python3.12/site-packages/airflow/models/taskinstance.py", line 432, in _execute_callable
    return execute_callable(context=context, **execute_callable_kwargs)
           ^^^^^^^^^^^^^^^^^^^^^^^^^^^^^^^^^^^^^^^^^^^^^^^^^^^^^^^^^^^^
  File "/home/airflow/.local/lib/python3.12/site-packages/airflow/models/baseoperator.py", line 401, in wrapper
    return func(self, *args, **kwargs)
           ^^^^^^^^^^^^^^^^^^^^^^^^^^^
  File "/home/airflow/.local/lib/python3.12/site-packages/airflow/decorators/base.py", line 265, in execute
    return_value = super().execute(context)
                   ^^^^^^^^^^^^^^^^^^^^^^^^
  File "/home/airflow/.local/lib/python3.12/site-packages/airflow/models/baseoperator.py", line 401, in wrapper
    return func(self, *args, **kwargs)
           ^^^^^^^^^^^^^^^^^^^^^^^^^^^
  File "/home/airflow/.local/lib/python3.12/site-packages/airflow/operators/python.py", line 235, in execute
    return_value = self.execute_callable()
                   ^^^^^^^^^^^^^^^^^^^^^^^
  File "/home/airflow/.local/lib/python3.12/site-packages/airflow/operators/python.py", line 252, in execute_callable
    return self.python_callable(*self.op_args, **self.op_kwargs)
           ^^^^^^^^^^^^^^^^^^^^^^^^^^^^^^^^^^^^^^^^^^^^^^^^^^^^^
  File "/opt/airflow/dags/country_capital_to_snowflake_v1.py", line 63, in load
    cur = return_snowflake_conn()
          ^^^^^^^^^^^^^^^^^^^^^^^
  File "/opt/airflow/dags/country_capital_to_snowflake_v1.py", line 20, in return_snowflake_conn
    conn = snowflake.connector.connect(
           ^^^^^^^^^^^^^^^^^^^^^^^^^^^^
  File "/home/airflow/.local/lib/python3.12/site-packages/snowflake/connector/__init__.py", line 55, in Connect
    return SnowflakeConnection(**kwargs)
           ^^^^^^^^^^^^^^^^^^^^^^^^^^^^^
  File "/home/airflow/.local/lib/python3.12/site-packages/snowflake/connector/connection.py", line 451, in __init__
    self.connect(**kwargs)
  File "/home/airflow/.local/lib/python3.12/site-packages/snowflake/connector/connection.py", line 756, in connect
    self.__open_connection()
  File "/home/airflow/.local/lib/python3.12/site-packages/snowflake/connector/connection.py", line 1084, in __open_connection
    self.authenticate_with_retry(self.auth_class)
  File "/home/airflow/.local/lib/python3.12/site-packages/snowflake/connector/connection.py", line 1364, in authenticate_with_retry
    self._authenticate(auth_instance)
  File "/home/airflow/.local/lib/python3.12/site-packages/snowflake/connector/connection.py", line 1392, in _authenticate
    auth.authenticate(
  File "/home/airflow/.local/lib/python3.12/site-packages/snowflake/connector/auth/_auth.py", line 401, in authenticate
    Error.errorhandler_wrapper(
  File "/home/airflow/.local/lib/python3.12/site-packages/snowflake/connector/errors.py", line 290, in errorhandler_wrapper
    handed_over = Error.hand_to_other_handler(
                  ^^^^^^^^^^^^^^^^^^^^^^^^^^^^
  File "/home/airflow/.local/lib/python3.12/site-packages/snowflake/connector/errors.py", line 348, in hand_to_other_handler
    connection.errorhandler(connection, cursor, error_class, error_value)
  File "/home/airflow/.local/lib/python3.12/site-packages/snowflake/connector/errors.py", line 221, in default_errorhandler
    raise error_class(
snowflake.connector.errors.DatabaseError: 250001 (08001): None: Failed to connect to DB: SFEDU02-LVB17920.snowflakecomputing.com:443. Incorrect username or password was specified.
[2025-10-01T22:15:58.438+0000] {taskinstance.py:1206} INFO - Marking task as FAILED. dag_id=CountryCaptial_v1, task_id=load, run_id=manual__2025-10-01T22:15:53.779539+00:00, execution_date=20251001T221553, start_date=20251001T221558, end_date=20251001T221558
[2025-10-01T22:15:58.444+0000] {standard_task_runner.py:110} ERROR - Failed to execute job 493 for task load (250001 (08001): None: Failed to connect to DB: SFEDU02-LVB17920.snowflakecomputing.com:443. Incorrect username or password was specified.; 6465)
[2025-10-01T22:15:58.488+0000] {local_task_job_runner.py:243} INFO - Task exited with return code 1
[2025-10-01T22:15:58.496+0000] {taskinstance.py:3503} INFO - 0 downstream tasks scheduled from follow-on schedule check
[2025-10-01T22:15:58.497+0000] {local_task_job_runner.py:222} INFO - ::endgroup::
