[2025-09-25T23:46:04.511+0000] {local_task_job_runner.py:120} INFO - ::group::Pre task execution logs
[2025-09-25T23:46:04.521+0000] {taskinstance.py:2076} INFO - Dependencies all met for dep_context=non-requeueable deps ti=<TaskInstance: ml_forecast_stock_robust.check_upstream_success manual__2025-09-25T23:25:27.949280+00:00 [queued]>
[2025-09-25T23:46:04.524+0000] {taskinstance.py:2076} INFO - Dependencies all met for dep_context=requeueable deps ti=<TaskInstance: ml_forecast_stock_robust.check_upstream_success manual__2025-09-25T23:25:27.949280+00:00 [queued]>
[2025-09-25T23:46:04.524+0000] {taskinstance.py:2306} INFO - Starting attempt 2 of 3
[2025-09-25T23:46:04.531+0000] {taskinstance.py:2330} INFO - Executing <Task(PythonOperator): check_upstream_success> on 2025-09-25 23:25:27.949280+00:00
[2025-09-25T23:46:04.536+0000] {warnings.py:112} WARNING - /home/***/.local/lib/python3.12/site-packages/***/task/task_runner/standard_task_runner.py:62: DeprecationWarning: This process (pid=17732) is multi-threaded, use of fork() may lead to deadlocks in the child.
  pid = os.fork()

[2025-09-25T23:46:04.537+0000] {standard_task_runner.py:64} INFO - Started process 17734 to run task
[2025-09-25T23:46:04.537+0000] {standard_task_runner.py:90} INFO - Running: ['***', 'tasks', 'run', 'ml_forecast_stock_robust', 'check_upstream_success', 'manual__2025-09-25T23:25:27.949280+00:00', '--job-id', '403', '--raw', '--subdir', 'DAGS_FOLDER/ml_forecast_stock.py', '--cfg-path', '/tmp/tmp67pj5sfv']
[2025-09-25T23:46:04.538+0000] {standard_task_runner.py:91} INFO - Job 403: Subtask check_upstream_success
[2025-09-25T23:46:04.562+0000] {task_command.py:426} INFO - Running <TaskInstance: ml_forecast_stock_robust.check_upstream_success manual__2025-09-25T23:25:27.949280+00:00 [running]> on host 11e1994bdecf
[2025-09-25T23:46:04.595+0000] {taskinstance.py:2648} INFO - Exporting env vars: AIRFLOW_CTX_DAG_OWNER='data226' AIRFLOW_CTX_DAG_ID='ml_forecast_stock_robust' AIRFLOW_CTX_TASK_ID='check_upstream_success' AIRFLOW_CTX_EXECUTION_DATE='2025-09-25T23:25:27.949280+00:00' AIRFLOW_CTX_TRY_NUMBER='2' AIRFLOW_CTX_DAG_RUN_ID='manual__2025-09-25T23:25:27.949280+00:00'
[2025-09-25T23:46:04.596+0000] {taskinstance.py:430} INFO - ::endgroup::
[2025-09-25T23:46:04.600+0000] {warnings.py:112} WARNING - /home/***/.local/lib/python3.12/site-packages/***/utils/context.py:320: AirflowContextDeprecationWarning: Accessing 'execution_date' from the template is deprecated and will be removed in a future version. Please use 'data_interval_start' or 'logical_date' instead.
  warnings.warn(_create_deprecation_warning(k, replacements))

[2025-09-25T23:46:04.600+0000] {taskinstance.py:441} INFO - ::group::Post task execution logs
[2025-09-25T23:46:04.600+0000] {taskinstance.py:2905} ERROR - Task failed with exception
Traceback (most recent call last):
  File "/home/airflow/.local/lib/python3.12/site-packages/airflow/models/taskinstance.py", line 465, in _execute_task
    result = _execute_callable(context=context, **execute_callable_kwargs)
             ^^^^^^^^^^^^^^^^^^^^^^^^^^^^^^^^^^^^^^^^^^^^^^^^^^^^^^^^^^^^^
  File "/home/airflow/.local/lib/python3.12/site-packages/airflow/models/taskinstance.py", line 432, in _execute_callable
    return execute_callable(context=context, **execute_callable_kwargs)
           ^^^^^^^^^^^^^^^^^^^^^^^^^^^^^^^^^^^^^^^^^^^^^^^^^^^^^^^^^^^^
  File "/home/airflow/.local/lib/python3.12/site-packages/airflow/models/baseoperator.py", line 401, in wrapper
    return func(self, *args, **kwargs)
           ^^^^^^^^^^^^^^^^^^^^^^^^^^^
  File "/home/airflow/.local/lib/python3.12/site-packages/airflow/operators/python.py", line 235, in execute
    return_value = self.execute_callable()
                   ^^^^^^^^^^^^^^^^^^^^^^^
  File "/home/airflow/.local/lib/python3.12/site-packages/airflow/operators/python.py", line 252, in execute_callable
    return self.python_callable(*self.op_args, **self.op_kwargs)
           ^^^^^^^^^^^^^^^^^^^^^^^^^^^^^^^^^^^^^^^^^^^^^^^^^^^^^
  File "/opt/airflow/dags/ml_forecast_stock.py", line 166, in check_upstream_task_success
    start_datetime = timezone.datetime.combine(target_date, datetime.min.time())
                     ^^^^^^^^^^^^^^^^^^^^^^^^^
AttributeError: 'function' object has no attribute 'combine'
[2025-09-25T23:46:04.604+0000] {taskinstance.py:1206} INFO - Marking task as UP_FOR_RETRY. dag_id=ml_forecast_stock_robust, task_id=check_upstream_success, run_id=manual__2025-09-25T23:25:27.949280+00:00, execution_date=20250925T232527, start_date=20250925T234604, end_date=20250925T234604
[2025-09-25T23:46:04.609+0000] {standard_task_runner.py:110} ERROR - Failed to execute job 403 for task check_upstream_success ('function' object has no attribute 'combine'; 17734)
[2025-09-25T23:46:04.637+0000] {local_task_job_runner.py:243} INFO - Task exited with return code 1
[2025-09-25T23:46:04.647+0000] {taskinstance.py:3503} INFO - 0 downstream tasks scheduled from follow-on schedule check
[2025-09-25T23:46:04.648+0000] {local_task_job_runner.py:222} INFO - ::endgroup::
