[2025-10-01T21:43:33.066+0000] {local_task_job_runner.py:120} INFO - ::group::Pre task execution logs
[2025-10-01T21:43:33.077+0000] {taskinstance.py:2076} INFO - Dependencies all met for dep_context=non-requeueable deps ti=<TaskInstance: CountryCaptial_v2.load scheduled__2025-09-30T02:30:00+00:00 [queued]>
[2025-10-01T21:43:33.081+0000] {taskinstance.py:2076} INFO - Dependencies all met for dep_context=requeueable deps ti=<TaskInstance: CountryCaptial_v2.load scheduled__2025-09-30T02:30:00+00:00 [queued]>
[2025-10-01T21:43:33.081+0000] {taskinstance.py:2306} INFO - Starting attempt 1 of 1
[2025-10-01T21:43:33.088+0000] {taskinstance.py:2330} INFO - Executing <Task(_PythonDecoratedOperator): load> on 2025-09-30 02:30:00+00:00
[2025-10-01T21:43:33.095+0000] {warnings.py:112} WARNING - /home/***/.local/lib/python3.12/site-packages/***/task/task_runner/standard_task_runner.py:62: DeprecationWarning: This process (pid=5927) is multi-threaded, use of fork() may lead to deadlocks in the child.
  pid = os.fork()

[2025-10-01T21:43:33.098+0000] {standard_task_runner.py:64} INFO - Started process 5934 to run task
[2025-10-01T21:43:33.097+0000] {standard_task_runner.py:90} INFO - Running: ['***', 'tasks', 'run', 'CountryCaptial_v2', 'load', 'scheduled__2025-09-30T02:30:00+00:00', '--job-id', '460', '--raw', '--subdir', 'DAGS_FOLDER/country_capital_to_snowflake_v2.py', '--cfg-path', '/tmp/tmpiibware0']
[2025-10-01T21:43:33.099+0000] {standard_task_runner.py:91} INFO - Job 460: Subtask load
[2025-10-01T21:43:33.158+0000] {task_command.py:426} INFO - Running <TaskInstance: CountryCaptial_v2.load scheduled__2025-09-30T02:30:00+00:00 [running]> on host 11e1994bdecf
[2025-10-01T21:43:33.256+0000] {taskinstance.py:2648} INFO - Exporting env vars: AIRFLOW_CTX_DAG_OWNER='***' AIRFLOW_CTX_DAG_ID='CountryCaptial_v2' AIRFLOW_CTX_TASK_ID='load' AIRFLOW_CTX_EXECUTION_DATE='2025-09-30T02:30:00+00:00' AIRFLOW_CTX_TRY_NUMBER='1' AIRFLOW_CTX_DAG_RUN_ID='scheduled__2025-09-30T02:30:00+00:00'
[2025-10-01T21:43:33.257+0000] {taskinstance.py:430} INFO - ::endgroup::
[2025-10-01T21:43:33.262+0000] {taskinstance.py:441} INFO - ::group::Post task execution logs
[2025-10-01T21:43:33.268+0000] {taskinstance.py:2905} ERROR - Task failed with exception
Traceback (most recent call last):
  File "/home/airflow/.local/lib/python3.12/site-packages/airflow/models/taskinstance.py", line 465, in _execute_task
    result = _execute_callable(context=context, **execute_callable_kwargs)
             ^^^^^^^^^^^^^^^^^^^^^^^^^^^^^^^^^^^^^^^^^^^^^^^^^^^^^^^^^^^^^
  File "/home/airflow/.local/lib/python3.12/site-packages/airflow/models/taskinstance.py", line 432, in _execute_callable
    return execute_callable(context=context, **execute_callable_kwargs)
           ^^^^^^^^^^^^^^^^^^^^^^^^^^^^^^^^^^^^^^^^^^^^^^^^^^^^^^^^^^^^
  File "/home/airflow/.local/lib/python3.12/site-packages/airflow/models/baseoperator.py", line 401, in wrapper
    return func(self, *args, **kwargs)
           ^^^^^^^^^^^^^^^^^^^^^^^^^^^
  File "/home/airflow/.local/lib/python3.12/site-packages/airflow/decorators/base.py", line 265, in execute
    return_value = super().execute(context)
                   ^^^^^^^^^^^^^^^^^^^^^^^^
  File "/home/airflow/.local/lib/python3.12/site-packages/airflow/models/baseoperator.py", line 401, in wrapper
    return func(self, *args, **kwargs)
           ^^^^^^^^^^^^^^^^^^^^^^^^^^^
  File "/home/airflow/.local/lib/python3.12/site-packages/airflow/operators/python.py", line 235, in execute
    return_value = self.execute_callable()
                   ^^^^^^^^^^^^^^^^^^^^^^^
  File "/home/airflow/.local/lib/python3.12/site-packages/airflow/operators/python.py", line 252, in execute_callable
    return self.python_callable(*self.op_args, **self.op_kwargs)
           ^^^^^^^^^^^^^^^^^^^^^^^^^^^^^^^^^^^^^^^^^^^^^^^^^^^^^
  File "/opt/airflow/dags/country_capital_to_snowflake_v2.py", line 53, in load
    cur = return_snowflake_conn()
          ^^^^^^^^^^^^^^^^^^^^^^^
  File "/opt/airflow/dags/country_capital_to_snowflake_v2.py", line 18, in return_snowflake_conn
    conn = hook.get_conn()
           ^^^^^^^^^^^^^^^
  File "/home/airflow/.local/lib/python3.12/site-packages/airflow/providers/snowflake/hooks/snowflake.py", line 299, in get_conn
    conn_config = self._get_conn_params
                  ^^^^^^^^^^^^^^^^^^^^^
  File "/usr/local/lib/python3.12/functools.py", line 995, in __get__
    val = self.func(instance)
          ^^^^^^^^^^^^^^^^^^^
  File "/home/airflow/.local/lib/python3.12/site-packages/airflow/providers/snowflake/hooks/snowflake.py", line 192, in _get_conn_params
    conn = self.get_connection(self.snowflake_conn_id)  # type: ignore[attr-defined]
           ^^^^^^^^^^^^^^^^^^^^^^^^^^^^^^^^^^^^^^^^^^^
  File "/home/airflow/.local/lib/python3.12/site-packages/airflow/hooks/base.py", line 83, in get_connection
    conn = Connection.get_connection_from_secrets(conn_id)
           ^^^^^^^^^^^^^^^^^^^^^^^^^^^^^^^^^^^^^^^^^^^^^^^
  File "/home/airflow/.local/lib/python3.12/site-packages/airflow/models/connection.py", line 519, in get_connection_from_secrets
    raise AirflowNotFoundException(f"The conn_id `{conn_id}` isn't defined")
airflow.exceptions.AirflowNotFoundException: The conn_id `snowflake_conn` isn't defined
[2025-10-01T21:43:33.280+0000] {taskinstance.py:1206} INFO - Marking task as FAILED. dag_id=CountryCaptial_v2, task_id=load, run_id=scheduled__2025-09-30T02:30:00+00:00, execution_date=20250930T023000, start_date=20251001T214333, end_date=20251001T214333
[2025-10-01T21:43:33.296+0000] {standard_task_runner.py:110} ERROR - Failed to execute job 460 for task load (The conn_id `snowflake_conn` isn't defined; 5934)
[2025-10-01T21:43:33.319+0000] {local_task_job_runner.py:243} INFO - Task exited with return code 1
[2025-10-01T21:43:33.326+0000] {taskinstance.py:3503} INFO - 0 downstream tasks scheduled from follow-on schedule check
[2025-10-01T21:43:33.327+0000] {local_task_job_runner.py:222} INFO - ::endgroup::
