[2025-09-30T00:13:49.537+0000] {local_task_job_runner.py:120} INFO - ::group::Pre task execution logs
[2025-09-30T00:13:49.544+0000] {taskinstance.py:2076} INFO - Dependencies all met for dep_context=non-requeueable deps ti=<TaskInstance: ml_forecast_stock_robust.run_forecast scheduled__2025-09-29T00:00:00+00:00 [queued]>
[2025-09-30T00:13:49.547+0000] {taskinstance.py:2076} INFO - Dependencies all met for dep_context=requeueable deps ti=<TaskInstance: ml_forecast_stock_robust.run_forecast scheduled__2025-09-29T00:00:00+00:00 [queued]>
[2025-09-30T00:13:49.547+0000] {taskinstance.py:2306} INFO - Starting attempt 1 of 3
[2025-09-30T00:13:49.551+0000] {taskinstance.py:2330} INFO - Executing <Task(PythonOperator): run_forecast> on 2025-09-29 00:00:00+00:00
[2025-09-30T00:13:49.556+0000] {warnings.py:112} WARNING - /home/***/.local/lib/python3.12/site-packages/***/task/task_runner/standard_task_runner.py:62: DeprecationWarning: This process (pid=40028) is multi-threaded, use of fork() may lead to deadlocks in the child.
  pid = os.fork()

[2025-09-30T00:13:49.557+0000] {standard_task_runner.py:64} INFO - Started process 40030 to run task
[2025-09-30T00:13:49.557+0000] {standard_task_runner.py:90} INFO - Running: ['***', 'tasks', 'run', 'ml_forecast_stock_robust', 'run_forecast', 'scheduled__2025-09-29T00:00:00+00:00', '--job-id', '442', '--raw', '--subdir', 'DAGS_FOLDER/ml_forecast_stock.py', '--cfg-path', '/tmp/tmp542m4cqo']
[2025-09-30T00:13:49.558+0000] {standard_task_runner.py:91} INFO - Job 442: Subtask run_forecast
[2025-09-30T00:13:49.574+0000] {task_command.py:426} INFO - Running <TaskInstance: ml_forecast_stock_robust.run_forecast scheduled__2025-09-29T00:00:00+00:00 [running]> on host 11e1994bdecf
[2025-09-30T00:13:49.600+0000] {taskinstance.py:2648} INFO - Exporting env vars: AIRFLOW_CTX_DAG_OWNER='data226' AIRFLOW_CTX_DAG_ID='ml_forecast_stock_robust' AIRFLOW_CTX_TASK_ID='run_forecast' AIRFLOW_CTX_EXECUTION_DATE='2025-09-29T00:00:00+00:00' AIRFLOW_CTX_TRY_NUMBER='1' AIRFLOW_CTX_DAG_RUN_ID='scheduled__2025-09-29T00:00:00+00:00'
[2025-09-30T00:13:49.600+0000] {taskinstance.py:430} INFO - ::endgroup::
[2025-09-30T00:13:49.610+0000] {base.py:84} INFO - Using connection ID 'snowflake_default' for task execution.
[2025-09-30T00:13:49.611+0000] {connection.py:408} INFO - Snowflake Connector for Python Version: 3.11.0, Python Version: 3.12.4, Platform: Linux-6.10.14-linuxkit-aarch64-with-glibc2.36
[2025-09-30T00:13:49.611+0000] {connection.py:1258} INFO - This connection is in OCSP Fail Open Mode. TLS Certificates would be checked for validity and revocation status. Any other Certificate Revocation related exceptions or OCSP Responder failures would be disregarded in favor of connectivity.
[2025-09-30T00:13:50.153+0000] {cursor.py:1149} INFO - Number of results in first chunk: 1
[2025-09-30T00:13:50.285+0000] {cursor.py:1149} INFO - Number of results in first chunk: 1
[2025-09-30T00:13:50.462+0000] {cursor.py:1149} INFO - Number of results in first chunk: 1
[2025-09-30T00:13:50.463+0000] {ml_forecast_stock.py:223} INFO - Using: warehouse="BEETLE_QUERY_WH", database="ASH_DB", schema="STOCK_SCHEMA"
[2025-09-30T00:13:50.641+0000] {cursor.py:1149} INFO - Number of results in first chunk: 1
[2025-09-30T00:13:50.642+0000] {ml_forecast_stock.py:231} INFO - Executing SQL statement 1/2
[2025-09-30T00:22:42.870+0000] {local_task_job_runner.py:313} WARNING - State of this instance has been externally set to up_for_retry. Terminating instance.
[2025-09-30T00:22:42.872+0000] {local_task_job_runner.py:222} INFO - ::endgroup::
[2025-09-30T00:22:42.875+0000] {process_utils.py:132} INFO - Sending 15 to group 40030. PIDs of all processes in the group: [40030]
[2025-09-30T00:22:42.875+0000] {process_utils.py:87} INFO - Sending the signal 15 to group 40030
[2025-09-30T00:22:42.876+0000] {taskinstance.py:2611} ERROR - Received SIGTERM. Terminating subprocesses.
[2025-09-30T00:22:42.881+0000] {connection.py:773} INFO - closed
[2025-09-30T00:22:42.911+0000] {connectionpool.py:824} WARNING - Retrying (Retry(total=0, connect=None, read=None, redirect=None, status=None)) after connection broken by 'NewConnectionError('<snowflake.connector.vendored.urllib3.connection.HTTPSConnection object at 0xffff5d7a57f0>: Failed to establish a new connection: [Errno -2] Name or service not known')': /telemetry/send?request_guid=b4a170e5-520f-45ca-9bd4-430418856b5a
[2025-09-30T00:22:43.926+0000] {connectionpool.py:824} WARNING - Retrying (Retry(total=0, connect=None, read=None, redirect=None, status=None)) after connection broken by 'NewConnectionError('<snowflake.connector.vendored.urllib3.connection.HTTPSConnection object at 0xffff5d7a61b0>: Failed to establish a new connection: [Errno -2] Name or service not known')': /telemetry/send?request_guid=b34a94cf-3b69-45c4-83b6-a8789a9bac66
[2025-09-30T00:22:44.935+0000] {connectionpool.py:824} WARNING - Retrying (Retry(total=0, connect=None, read=None, redirect=None, status=None)) after connection broken by 'NewConnectionError('<snowflake.connector.vendored.urllib3.connection.HTTPSConnection object at 0xffff5d7a4980>: Failed to establish a new connection: [Errno -2] Name or service not known')': /telemetry/send?request_guid=b05234cd-c7c9-41f6-8517-e8f662655dd7
[2025-09-30T00:22:46.947+0000] {connectionpool.py:824} WARNING - Retrying (Retry(total=0, connect=None, read=None, redirect=None, status=None)) after connection broken by 'NewConnectionError('<snowflake.connector.vendored.urllib3.connection.HTTPSConnection object at 0xffff5d7a7260>: Failed to establish a new connection: [Errno -2] Name or service not known')': /telemetry/send?request_guid=de702188-b9bd-4e93-ae96-eb6bf4518fad
[2025-09-30T00:22:51.963+0000] {connectionpool.py:824} WARNING - Retrying (Retry(total=0, connect=None, read=None, redirect=None, status=None)) after connection broken by 'NewConnectionError('<snowflake.connector.vendored.urllib3.connection.HTTPSConnection object at 0xffff5d7a44a0>: Failed to establish a new connection: [Errno -2] Name or service not known')': /telemetry/send?request_guid=1fa83e68-761d-4baf-9828-6969dc9ecdb6
[2025-09-30T00:22:51.970+0000] {network.py:994} ERROR - HTTPSConnectionPool(host='sfedu02-lvb17920.snowflakecomputing.com', port=443): Max retries exceeded with url: /telemetry/send?request_guid=1fa83e68-761d-4baf-9828-6969dc9ecdb6 (Caused by NewConnectionError('<snowflake.connector.vendored.urllib3.connection.HTTPSConnection object at 0xffff5d7a6120>: Failed to establish a new connection: [Errno -2] Name or service not known'))
Traceback (most recent call last):
  File "/opt/airflow/dags/ml_forecast_stock.py", line 233, in execute_snowflake_with_retry
    cs.execute(final_sql)
  File "/home/airflow/.local/lib/python3.12/site-packages/snowflake/connector/cursor.py", line 977, in execute
    ret = self._execute_helper(query, **kwargs)
          ^^^^^^^^^^^^^^^^^^^^^^^^^^^^^^^^^^^^^
  File "/home/airflow/.local/lib/python3.12/site-packages/snowflake/connector/cursor.py", line 694, in _execute_helper
    ret = self._connection.cmd_query(
          ^^^^^^^^^^^^^^^^^^^^^^^^^^^
  File "/home/airflow/.local/lib/python3.12/site-packages/snowflake/connector/connection.py", line 1328, in cmd_query
    ret = self.rest.request(
          ^^^^^^^^^^^^^^^^^^
  File "/home/airflow/.local/lib/python3.12/site-packages/snowflake/connector/network.py", line 493, in request
    return self._post_request(
           ^^^^^^^^^^^^^^^^^^^
  File "/home/airflow/.local/lib/python3.12/site-packages/snowflake/connector/network.py", line 734, in _post_request
    ret = self.fetch(
          ^^^^^^^^^^^
  File "/home/airflow/.local/lib/python3.12/site-packages/snowflake/connector/network.py", line 843, in fetch
    ret = self._request_exec_wrapper(
          ^^^^^^^^^^^^^^^^^^^^^^^^^^^
  File "/home/airflow/.local/lib/python3.12/site-packages/snowflake/connector/network.py", line 884, in _request_exec_wrapper
    return_object = self._request_exec(
                    ^^^^^^^^^^^^^^^^^^^
  File "/home/airflow/.local/lib/python3.12/site-packages/snowflake/connector/network.py", line 1078, in _request_exec
    raw_ret = session.request(
              ^^^^^^^^^^^^^^^^
  File "/home/airflow/.local/lib/python3.12/site-packages/snowflake/connector/vendored/requests/sessions.py", line 589, in request
    resp = self.send(prep, **send_kwargs)
           ^^^^^^^^^^^^^^^^^^^^^^^^^^^^^^
  File "/home/airflow/.local/lib/python3.12/site-packages/snowflake/connector/vendored/requests/sessions.py", line 703, in send
    r = adapter.send(request, **kwargs)
        ^^^^^^^^^^^^^^^^^^^^^^^^^^^^^^^
  File "/home/airflow/.local/lib/python3.12/site-packages/snowflake/connector/vendored/requests/adapters.py", line 486, in send
    resp = conn.urlopen(
           ^^^^^^^^^^^^^
  File "/home/airflow/.local/lib/python3.12/site-packages/snowflake/connector/vendored/urllib3/connectionpool.py", line 715, in urlopen
    httplib_response = self._make_request(
                       ^^^^^^^^^^^^^^^^^^^
  File "/home/airflow/.local/lib/python3.12/site-packages/snowflake/connector/vendored/urllib3/connectionpool.py", line 467, in _make_request
    six.raise_from(e, None)
  File "<string>", line 3, in raise_from
  File "/home/airflow/.local/lib/python3.12/site-packages/snowflake/connector/vendored/urllib3/connectionpool.py", line 462, in _make_request
    httplib_response = conn.getresponse()
                       ^^^^^^^^^^^^^^^^^^
  File "/usr/local/lib/python3.12/http/client.py", line 1428, in getresponse
    response.begin()
  File "/usr/local/lib/python3.12/http/client.py", line 331, in begin
    version, status, reason = self._read_status()
                              ^^^^^^^^^^^^^^^^^^^
  File "/usr/local/lib/python3.12/http/client.py", line 292, in _read_status
    line = str(self.fp.readline(_MAXLINE + 1), "iso-8859-1")
               ^^^^^^^^^^^^^^^^^^^^^^^^^^^^^^
  File "/usr/local/lib/python3.12/socket.py", line 708, in readinto
    return self._sock.recv_into(b)
           ^^^^^^^^^^^^^^^^^^^^^^^
  File "/home/airflow/.local/lib/python3.12/site-packages/snowflake/connector/vendored/urllib3/contrib/pyopenssl.py", line 330, in recv_into
    if not util.wait_for_read(self.socket, self.socket.gettimeout()):
           ^^^^^^^^^^^^^^^^^^^^^^^^^^^^^^^^^^^^^^^^^^^^^^^^^^^^^^^^^
  File "/home/airflow/.local/lib/python3.12/site-packages/snowflake/connector/vendored/urllib3/util/wait.py", line 145, in wait_for_read
    return wait_for_socket(sock, read=True, timeout=timeout)
           ^^^^^^^^^^^^^^^^^^^^^^^^^^^^^^^^^^^^^^^^^^^^^^^^^
  File "/home/airflow/.local/lib/python3.12/site-packages/snowflake/connector/vendored/urllib3/util/wait.py", line 106, in poll_wait_for_socket
    return bool(_retry_on_intr(do_poll, timeout))
                ^^^^^^^^^^^^^^^^^^^^^^^^^^^^^^^^
  File "/home/airflow/.local/lib/python3.12/site-packages/snowflake/connector/vendored/urllib3/util/wait.py", line 43, in _retry_on_intr
    return fn(timeout)
           ^^^^^^^^^^^
  File "/home/airflow/.local/lib/python3.12/site-packages/snowflake/connector/vendored/urllib3/util/wait.py", line 104, in do_poll
    return poll_obj.poll(t)
           ^^^^^^^^^^^^^^^^
  File "/home/airflow/.local/lib/python3.12/site-packages/airflow/models/taskinstance.py", line 2613, in signal_handler
    raise AirflowTaskTerminated("Task received SIGTERM signal")
airflow.exceptions.AirflowTaskTerminated: Task received SIGTERM signal

During handling of the above exception, another exception occurred:

Traceback (most recent call last):
  File "/home/airflow/.local/lib/python3.12/site-packages/snowflake/connector/vendored/urllib3/connection.py", line 174, in _new_conn
    conn = connection.create_connection(
           ^^^^^^^^^^^^^^^^^^^^^^^^^^^^^
  File "/home/airflow/.local/lib/python3.12/site-packages/snowflake/connector/vendored/urllib3/util/connection.py", line 79, in create_connection
    for res in socket.getaddrinfo(host, port, family, socket.SOCK_STREAM):
               ^^^^^^^^^^^^^^^^^^^^^^^^^^^^^^^^^^^^^^^^^^^^^^^^^^^^^^^^^^
  File "/usr/local/lib/python3.12/socket.py", line 964, in getaddrinfo
    for res in _socket.getaddrinfo(host, port, family, type, proto, flags):
               ^^^^^^^^^^^^^^^^^^^^^^^^^^^^^^^^^^^^^^^^^^^^^^^^^^^^^^^^^^^
socket.gaierror: [Errno -2] Name or service not known

During handling of the above exception, another exception occurred:

Traceback (most recent call last):
  File "/home/airflow/.local/lib/python3.12/site-packages/snowflake/connector/vendored/urllib3/connectionpool.py", line 715, in urlopen
    httplib_response = self._make_request(
                       ^^^^^^^^^^^^^^^^^^^
  File "/home/airflow/.local/lib/python3.12/site-packages/snowflake/connector/vendored/urllib3/connectionpool.py", line 404, in _make_request
    self._validate_conn(conn)
  File "/home/airflow/.local/lib/python3.12/site-packages/snowflake/connector/vendored/urllib3/connectionpool.py", line 1058, in _validate_conn
    conn.connect()
  File "/home/airflow/.local/lib/python3.12/site-packages/snowflake/connector/vendored/urllib3/connection.py", line 363, in connect
    self.sock = conn = self._new_conn()
                       ^^^^^^^^^^^^^^^^
  File "/home/airflow/.local/lib/python3.12/site-packages/snowflake/connector/vendored/urllib3/connection.py", line 186, in _new_conn
    raise NewConnectionError(
snowflake.connector.vendored.urllib3.exceptions.NewConnectionError: <snowflake.connector.vendored.urllib3.connection.HTTPSConnection object at 0xffff5d7a6120>: Failed to establish a new connection: [Errno -2] Name or service not known

During handling of the above exception, another exception occurred:

Traceback (most recent call last):
  File "/home/airflow/.local/lib/python3.12/site-packages/snowflake/connector/vendored/requests/adapters.py", line 486, in send
    resp = conn.urlopen(
           ^^^^^^^^^^^^^
  File "/home/airflow/.local/lib/python3.12/site-packages/snowflake/connector/vendored/urllib3/connectionpool.py", line 827, in urlopen
    return self.urlopen(
           ^^^^^^^^^^^^^
  File "/home/airflow/.local/lib/python3.12/site-packages/snowflake/connector/vendored/urllib3/connectionpool.py", line 799, in urlopen
    retries = retries.increment(
              ^^^^^^^^^^^^^^^^^^
  File "/home/airflow/.local/lib/python3.12/site-packages/snowflake/connector/vendored/urllib3/util/retry.py", line 592, in increment
    raise MaxRetryError(_pool, url, error or ResponseError(cause))
snowflake.connector.vendored.urllib3.exceptions.MaxRetryError: HTTPSConnectionPool(host='sfedu02-lvb17920.snowflakecomputing.com', port=443): Max retries exceeded with url: /telemetry/send?request_guid=1fa83e68-761d-4baf-9828-6969dc9ecdb6 (Caused by NewConnectionError('<snowflake.connector.vendored.urllib3.connection.HTTPSConnection object at 0xffff5d7a6120>: Failed to establish a new connection: [Errno -2] Name or service not known'))

During handling of the above exception, another exception occurred:

Traceback (most recent call last):
  File "/home/airflow/.local/lib/python3.12/site-packages/snowflake/connector/network.py", line 1078, in _request_exec
    raw_ret = session.request(
              ^^^^^^^^^^^^^^^^
  File "/home/airflow/.local/lib/python3.12/site-packages/snowflake/connector/vendored/requests/sessions.py", line 589, in request
    resp = self.send(prep, **send_kwargs)
           ^^^^^^^^^^^^^^^^^^^^^^^^^^^^^^
  File "/home/airflow/.local/lib/python3.12/site-packages/snowflake/connector/vendored/requests/sessions.py", line 703, in send
    r = adapter.send(request, **kwargs)
        ^^^^^^^^^^^^^^^^^^^^^^^^^^^^^^^
  File "/home/airflow/.local/lib/python3.12/site-packages/snowflake/connector/vendored/requests/adapters.py", line 519, in send
    raise ConnectionError(e, request=request)
snowflake.connector.vendored.requests.exceptions.ConnectionError: HTTPSConnectionPool(host='sfedu02-lvb17920.snowflakecomputing.com', port=443): Max retries exceeded with url: /telemetry/send?request_guid=1fa83e68-761d-4baf-9828-6969dc9ecdb6 (Caused by NewConnectionError('<snowflake.connector.vendored.urllib3.connection.HTTPSConnection object at 0xffff5d7a6120>: Failed to establish a new connection: [Errno -2] Name or service not known'))

During handling of the above exception, another exception occurred:

Traceback (most recent call last):
  File "/home/airflow/.local/lib/python3.12/site-packages/snowflake/connector/network.py", line 884, in _request_exec_wrapper
    return_object = self._request_exec(
                    ^^^^^^^^^^^^^^^^^^^
  File "/home/airflow/.local/lib/python3.12/site-packages/snowflake/connector/network.py", line 1182, in _request_exec
    raise RetryRequest(err)
snowflake.connector.network.RetryRequest: HTTPSConnectionPool(host='sfedu02-lvb17920.snowflakecomputing.com', port=443): Max retries exceeded with url: /telemetry/send?request_guid=1fa83e68-761d-4baf-9828-6969dc9ecdb6 (Caused by NewConnectionError('<snowflake.connector.vendored.urllib3.connection.HTTPSConnection object at 0xffff5d7a6120>: Failed to establish a new connection: [Errno -2] Name or service not known'))
[2025-09-30T00:22:51.998+0000] {connection.py:779} INFO - No async queries seem to be running, deleting session
[2025-09-30T00:22:52.003+0000] {connectionpool.py:824} WARNING - Retrying (Retry(total=0, connect=None, read=None, redirect=None, status=None)) after connection broken by 'NewConnectionError('<snowflake.connector.vendored.urllib3.connection.HTTPSConnection object at 0xffff5d532810>: Failed to establish a new connection: [Errno -2] Name or service not known')': /session?delete=true&request_guid=fcb0e53d-e78a-44a1-9063-94acc642b3f9
[2025-09-30T00:22:52.005+0000] {network.py:994} ERROR - HTTPSConnectionPool(host='sfedu02-lvb17920.snowflakecomputing.com', port=443): Max retries exceeded with url: /session?delete=true&request_guid=fcb0e53d-e78a-44a1-9063-94acc642b3f9 (Caused by NewConnectionError('<snowflake.connector.vendored.urllib3.connection.HTTPSConnection object at 0xffff5d532cc0>: Failed to establish a new connection: [Errno -2] Name or service not known'))
Traceback (most recent call last):
  File "/opt/airflow/dags/ml_forecast_stock.py", line 233, in execute_snowflake_with_retry
    cs.execute(final_sql)
  File "/home/airflow/.local/lib/python3.12/site-packages/snowflake/connector/cursor.py", line 977, in execute
    ret = self._execute_helper(query, **kwargs)
          ^^^^^^^^^^^^^^^^^^^^^^^^^^^^^^^^^^^^^
  File "/home/airflow/.local/lib/python3.12/site-packages/snowflake/connector/cursor.py", line 694, in _execute_helper
    ret = self._connection.cmd_query(
          ^^^^^^^^^^^^^^^^^^^^^^^^^^^
  File "/home/airflow/.local/lib/python3.12/site-packages/snowflake/connector/connection.py", line 1328, in cmd_query
    ret = self.rest.request(
          ^^^^^^^^^^^^^^^^^^
  File "/home/airflow/.local/lib/python3.12/site-packages/snowflake/connector/network.py", line 493, in request
    return self._post_request(
           ^^^^^^^^^^^^^^^^^^^
  File "/home/airflow/.local/lib/python3.12/site-packages/snowflake/connector/network.py", line 734, in _post_request
    ret = self.fetch(
          ^^^^^^^^^^^
  File "/home/airflow/.local/lib/python3.12/site-packages/snowflake/connector/network.py", line 843, in fetch
    ret = self._request_exec_wrapper(
          ^^^^^^^^^^^^^^^^^^^^^^^^^^^
  File "/home/airflow/.local/lib/python3.12/site-packages/snowflake/connector/network.py", line 884, in _request_exec_wrapper
    return_object = self._request_exec(
                    ^^^^^^^^^^^^^^^^^^^
  File "/home/airflow/.local/lib/python3.12/site-packages/snowflake/connector/network.py", line 1078, in _request_exec
    raw_ret = session.request(
              ^^^^^^^^^^^^^^^^
  File "/home/airflow/.local/lib/python3.12/site-packages/snowflake/connector/vendored/requests/sessions.py", line 589, in request
    resp = self.send(prep, **send_kwargs)
           ^^^^^^^^^^^^^^^^^^^^^^^^^^^^^^
  File "/home/airflow/.local/lib/python3.12/site-packages/snowflake/connector/vendored/requests/sessions.py", line 703, in send
    r = adapter.send(request, **kwargs)
        ^^^^^^^^^^^^^^^^^^^^^^^^^^^^^^^
  File "/home/airflow/.local/lib/python3.12/site-packages/snowflake/connector/vendored/requests/adapters.py", line 486, in send
    resp = conn.urlopen(
           ^^^^^^^^^^^^^
  File "/home/airflow/.local/lib/python3.12/site-packages/snowflake/connector/vendored/urllib3/connectionpool.py", line 715, in urlopen
    httplib_response = self._make_request(
                       ^^^^^^^^^^^^^^^^^^^
  File "/home/airflow/.local/lib/python3.12/site-packages/snowflake/connector/vendored/urllib3/connectionpool.py", line 467, in _make_request
    six.raise_from(e, None)
  File "<string>", line 3, in raise_from
  File "/home/airflow/.local/lib/python3.12/site-packages/snowflake/connector/vendored/urllib3/connectionpool.py", line 462, in _make_request
    httplib_response = conn.getresponse()
                       ^^^^^^^^^^^^^^^^^^
  File "/usr/local/lib/python3.12/http/client.py", line 1428, in getresponse
    response.begin()
  File "/usr/local/lib/python3.12/http/client.py", line 331, in begin
    version, status, reason = self._read_status()
                              ^^^^^^^^^^^^^^^^^^^
  File "/usr/local/lib/python3.12/http/client.py", line 292, in _read_status
    line = str(self.fp.readline(_MAXLINE + 1), "iso-8859-1")
               ^^^^^^^^^^^^^^^^^^^^^^^^^^^^^^
  File "/usr/local/lib/python3.12/socket.py", line 708, in readinto
    return self._sock.recv_into(b)
           ^^^^^^^^^^^^^^^^^^^^^^^
  File "/home/airflow/.local/lib/python3.12/site-packages/snowflake/connector/vendored/urllib3/contrib/pyopenssl.py", line 330, in recv_into
    if not util.wait_for_read(self.socket, self.socket.gettimeout()):
           ^^^^^^^^^^^^^^^^^^^^^^^^^^^^^^^^^^^^^^^^^^^^^^^^^^^^^^^^^
  File "/home/airflow/.local/lib/python3.12/site-packages/snowflake/connector/vendored/urllib3/util/wait.py", line 145, in wait_for_read
    return wait_for_socket(sock, read=True, timeout=timeout)
           ^^^^^^^^^^^^^^^^^^^^^^^^^^^^^^^^^^^^^^^^^^^^^^^^^
  File "/home/airflow/.local/lib/python3.12/site-packages/snowflake/connector/vendored/urllib3/util/wait.py", line 106, in poll_wait_for_socket
    return bool(_retry_on_intr(do_poll, timeout))
                ^^^^^^^^^^^^^^^^^^^^^^^^^^^^^^^^
  File "/home/airflow/.local/lib/python3.12/site-packages/snowflake/connector/vendored/urllib3/util/wait.py", line 43, in _retry_on_intr
    return fn(timeout)
           ^^^^^^^^^^^
  File "/home/airflow/.local/lib/python3.12/site-packages/snowflake/connector/vendored/urllib3/util/wait.py", line 104, in do_poll
    return poll_obj.poll(t)
           ^^^^^^^^^^^^^^^^
  File "/home/airflow/.local/lib/python3.12/site-packages/airflow/models/taskinstance.py", line 2613, in signal_handler
    raise AirflowTaskTerminated("Task received SIGTERM signal")
airflow.exceptions.AirflowTaskTerminated: Task received SIGTERM signal

During handling of the above exception, another exception occurred:

Traceback (most recent call last):
  File "/home/airflow/.local/lib/python3.12/site-packages/snowflake/connector/vendored/urllib3/connection.py", line 174, in _new_conn
    conn = connection.create_connection(
           ^^^^^^^^^^^^^^^^^^^^^^^^^^^^^
  File "/home/airflow/.local/lib/python3.12/site-packages/snowflake/connector/vendored/urllib3/util/connection.py", line 79, in create_connection
    for res in socket.getaddrinfo(host, port, family, socket.SOCK_STREAM):
               ^^^^^^^^^^^^^^^^^^^^^^^^^^^^^^^^^^^^^^^^^^^^^^^^^^^^^^^^^^
  File "/usr/local/lib/python3.12/socket.py", line 964, in getaddrinfo
    for res in _socket.getaddrinfo(host, port, family, type, proto, flags):
               ^^^^^^^^^^^^^^^^^^^^^^^^^^^^^^^^^^^^^^^^^^^^^^^^^^^^^^^^^^^
socket.gaierror: [Errno -2] Name or service not known

During handling of the above exception, another exception occurred:

Traceback (most recent call last):
  File "/home/airflow/.local/lib/python3.12/site-packages/snowflake/connector/vendored/urllib3/connectionpool.py", line 715, in urlopen
    httplib_response = self._make_request(
                       ^^^^^^^^^^^^^^^^^^^
  File "/home/airflow/.local/lib/python3.12/site-packages/snowflake/connector/vendored/urllib3/connectionpool.py", line 404, in _make_request
    self._validate_conn(conn)
  File "/home/airflow/.local/lib/python3.12/site-packages/snowflake/connector/vendored/urllib3/connectionpool.py", line 1058, in _validate_conn
    conn.connect()
  File "/home/airflow/.local/lib/python3.12/site-packages/snowflake/connector/vendored/urllib3/connection.py", line 363, in connect
    self.sock = conn = self._new_conn()
                       ^^^^^^^^^^^^^^^^
  File "/home/airflow/.local/lib/python3.12/site-packages/snowflake/connector/vendored/urllib3/connection.py", line 186, in _new_conn
    raise NewConnectionError(
snowflake.connector.vendored.urllib3.exceptions.NewConnectionError: <snowflake.connector.vendored.urllib3.connection.HTTPSConnection object at 0xffff5d532cc0>: Failed to establish a new connection: [Errno -2] Name or service not known

During handling of the above exception, another exception occurred:

Traceback (most recent call last):
  File "/home/airflow/.local/lib/python3.12/site-packages/snowflake/connector/vendored/requests/adapters.py", line 486, in send
    resp = conn.urlopen(
           ^^^^^^^^^^^^^
  File "/home/airflow/.local/lib/python3.12/site-packages/snowflake/connector/vendored/urllib3/connectionpool.py", line 827, in urlopen
    return self.urlopen(
           ^^^^^^^^^^^^^
  File "/home/airflow/.local/lib/python3.12/site-packages/snowflake/connector/vendored/urllib3/connectionpool.py", line 799, in urlopen
    retries = retries.increment(
              ^^^^^^^^^^^^^^^^^^
  File "/home/airflow/.local/lib/python3.12/site-packages/snowflake/connector/vendored/urllib3/util/retry.py", line 592, in increment
    raise MaxRetryError(_pool, url, error or ResponseError(cause))
snowflake.connector.vendored.urllib3.exceptions.MaxRetryError: HTTPSConnectionPool(host='sfedu02-lvb17920.snowflakecomputing.com', port=443): Max retries exceeded with url: /session?delete=true&request_guid=fcb0e53d-e78a-44a1-9063-94acc642b3f9 (Caused by NewConnectionError('<snowflake.connector.vendored.urllib3.connection.HTTPSConnection object at 0xffff5d532cc0>: Failed to establish a new connection: [Errno -2] Name or service not known'))

During handling of the above exception, another exception occurred:

Traceback (most recent call last):
  File "/home/airflow/.local/lib/python3.12/site-packages/snowflake/connector/network.py", line 1078, in _request_exec
    raw_ret = session.request(
              ^^^^^^^^^^^^^^^^
  File "/home/airflow/.local/lib/python3.12/site-packages/snowflake/connector/vendored/requests/sessions.py", line 589, in request
    resp = self.send(prep, **send_kwargs)
           ^^^^^^^^^^^^^^^^^^^^^^^^^^^^^^
  File "/home/airflow/.local/lib/python3.12/site-packages/snowflake/connector/vendored/requests/sessions.py", line 703, in send
    r = adapter.send(request, **kwargs)
        ^^^^^^^^^^^^^^^^^^^^^^^^^^^^^^^
  File "/home/airflow/.local/lib/python3.12/site-packages/snowflake/connector/vendored/requests/adapters.py", line 519, in send
    raise ConnectionError(e, request=request)
snowflake.connector.vendored.requests.exceptions.ConnectionError: HTTPSConnectionPool(host='sfedu02-lvb17920.snowflakecomputing.com', port=443): Max retries exceeded with url: /session?delete=true&request_guid=fcb0e53d-e78a-44a1-9063-94acc642b3f9 (Caused by NewConnectionError('<snowflake.connector.vendored.urllib3.connection.HTTPSConnection object at 0xffff5d532cc0>: Failed to establish a new connection: [Errno -2] Name or service not known'))

During handling of the above exception, another exception occurred:

Traceback (most recent call last):
  File "/home/airflow/.local/lib/python3.12/site-packages/snowflake/connector/network.py", line 884, in _request_exec_wrapper
    return_object = self._request_exec(
                    ^^^^^^^^^^^^^^^^^^^
  File "/home/airflow/.local/lib/python3.12/site-packages/snowflake/connector/network.py", line 1182, in _request_exec
    raise RetryRequest(err)
snowflake.connector.network.RetryRequest: HTTPSConnectionPool(host='sfedu02-lvb17920.snowflakecomputing.com', port=443): Max retries exceeded with url: /session?delete=true&request_guid=fcb0e53d-e78a-44a1-9063-94acc642b3f9 (Caused by NewConnectionError('<snowflake.connector.vendored.urllib3.connection.HTTPSConnection object at 0xffff5d532cc0>: Failed to establish a new connection: [Errno -2] Name or service not known'))
[2025-09-30T00:22:52.010+0000] {taskinstance.py:441} INFO - ::group::Post task execution logs
[2025-09-30T00:22:52.017+0000] {taskinstance.py:2905} ERROR - Task failed with exception
Traceback (most recent call last):
  File "/home/airflow/.local/lib/python3.12/site-packages/airflow/models/taskinstance.py", line 465, in _execute_task
    result = _execute_callable(context=context, **execute_callable_kwargs)
             ^^^^^^^^^^^^^^^^^^^^^^^^^^^^^^^^^^^^^^^^^^^^^^^^^^^^^^^^^^^^^
  File "/home/airflow/.local/lib/python3.12/site-packages/airflow/models/taskinstance.py", line 432, in _execute_callable
    return execute_callable(context=context, **execute_callable_kwargs)
           ^^^^^^^^^^^^^^^^^^^^^^^^^^^^^^^^^^^^^^^^^^^^^^^^^^^^^^^^^^^^
  File "/home/airflow/.local/lib/python3.12/site-packages/airflow/models/baseoperator.py", line 401, in wrapper
    return func(self, *args, **kwargs)
           ^^^^^^^^^^^^^^^^^^^^^^^^^^^
  File "/home/airflow/.local/lib/python3.12/site-packages/airflow/operators/python.py", line 235, in execute
    return_value = self.execute_callable()
                   ^^^^^^^^^^^^^^^^^^^^^^^
  File "/home/airflow/.local/lib/python3.12/site-packages/airflow/operators/python.py", line 252, in execute_callable
    return self.python_callable(*self.op_args, **self.op_kwargs)
           ^^^^^^^^^^^^^^^^^^^^^^^^^^^^^^^^^^^^^^^^^^^^^^^^^^^^^
  File "/opt/airflow/dags/ml_forecast_stock.py", line 330, in run_forecast_with_fallback
    success = execute_snowflake_with_retry(primary_sql, max_retries=2)
              ^^^^^^^^^^^^^^^^^^^^^^^^^^^^^^^^^^^^^^^^^^^^^^^^^^^^^^^^
  File "/opt/airflow/dags/ml_forecast_stock.py", line 233, in execute_snowflake_with_retry
    cs.execute(final_sql)
  File "/home/airflow/.local/lib/python3.12/site-packages/snowflake/connector/cursor.py", line 977, in execute
    ret = self._execute_helper(query, **kwargs)
          ^^^^^^^^^^^^^^^^^^^^^^^^^^^^^^^^^^^^^
  File "/home/airflow/.local/lib/python3.12/site-packages/snowflake/connector/cursor.py", line 694, in _execute_helper
    ret = self._connection.cmd_query(
          ^^^^^^^^^^^^^^^^^^^^^^^^^^^
  File "/home/airflow/.local/lib/python3.12/site-packages/snowflake/connector/connection.py", line 1328, in cmd_query
    ret = self.rest.request(
          ^^^^^^^^^^^^^^^^^^
  File "/home/airflow/.local/lib/python3.12/site-packages/snowflake/connector/network.py", line 493, in request
    return self._post_request(
           ^^^^^^^^^^^^^^^^^^^
  File "/home/airflow/.local/lib/python3.12/site-packages/snowflake/connector/network.py", line 734, in _post_request
    ret = self.fetch(
          ^^^^^^^^^^^
  File "/home/airflow/.local/lib/python3.12/site-packages/snowflake/connector/network.py", line 843, in fetch
    ret = self._request_exec_wrapper(
          ^^^^^^^^^^^^^^^^^^^^^^^^^^^
  File "/home/airflow/.local/lib/python3.12/site-packages/snowflake/connector/network.py", line 884, in _request_exec_wrapper
    return_object = self._request_exec(
                    ^^^^^^^^^^^^^^^^^^^
  File "/home/airflow/.local/lib/python3.12/site-packages/snowflake/connector/network.py", line 1078, in _request_exec
    raw_ret = session.request(
              ^^^^^^^^^^^^^^^^
  File "/home/airflow/.local/lib/python3.12/site-packages/snowflake/connector/vendored/requests/sessions.py", line 589, in request
    resp = self.send(prep, **send_kwargs)
           ^^^^^^^^^^^^^^^^^^^^^^^^^^^^^^
  File "/home/airflow/.local/lib/python3.12/site-packages/snowflake/connector/vendored/requests/sessions.py", line 703, in send
    r = adapter.send(request, **kwargs)
        ^^^^^^^^^^^^^^^^^^^^^^^^^^^^^^^
  File "/home/airflow/.local/lib/python3.12/site-packages/snowflake/connector/vendored/requests/adapters.py", line 486, in send
    resp = conn.urlopen(
           ^^^^^^^^^^^^^
  File "/home/airflow/.local/lib/python3.12/site-packages/snowflake/connector/vendored/urllib3/connectionpool.py", line 715, in urlopen
    httplib_response = self._make_request(
                       ^^^^^^^^^^^^^^^^^^^
  File "/home/airflow/.local/lib/python3.12/site-packages/snowflake/connector/vendored/urllib3/connectionpool.py", line 467, in _make_request
    six.raise_from(e, None)
  File "<string>", line 3, in raise_from
  File "/home/airflow/.local/lib/python3.12/site-packages/snowflake/connector/vendored/urllib3/connectionpool.py", line 462, in _make_request
    httplib_response = conn.getresponse()
                       ^^^^^^^^^^^^^^^^^^
  File "/usr/local/lib/python3.12/http/client.py", line 1428, in getresponse
    response.begin()
  File "/usr/local/lib/python3.12/http/client.py", line 331, in begin
    version, status, reason = self._read_status()
                              ^^^^^^^^^^^^^^^^^^^
  File "/usr/local/lib/python3.12/http/client.py", line 292, in _read_status
    line = str(self.fp.readline(_MAXLINE + 1), "iso-8859-1")
               ^^^^^^^^^^^^^^^^^^^^^^^^^^^^^^
  File "/usr/local/lib/python3.12/socket.py", line 708, in readinto
    return self._sock.recv_into(b)
           ^^^^^^^^^^^^^^^^^^^^^^^
  File "/home/airflow/.local/lib/python3.12/site-packages/snowflake/connector/vendored/urllib3/contrib/pyopenssl.py", line 330, in recv_into
    if not util.wait_for_read(self.socket, self.socket.gettimeout()):
           ^^^^^^^^^^^^^^^^^^^^^^^^^^^^^^^^^^^^^^^^^^^^^^^^^^^^^^^^^
  File "/home/airflow/.local/lib/python3.12/site-packages/snowflake/connector/vendored/urllib3/util/wait.py", line 145, in wait_for_read
    return wait_for_socket(sock, read=True, timeout=timeout)
           ^^^^^^^^^^^^^^^^^^^^^^^^^^^^^^^^^^^^^^^^^^^^^^^^^
  File "/home/airflow/.local/lib/python3.12/site-packages/snowflake/connector/vendored/urllib3/util/wait.py", line 106, in poll_wait_for_socket
    return bool(_retry_on_intr(do_poll, timeout))
                ^^^^^^^^^^^^^^^^^^^^^^^^^^^^^^^^
  File "/home/airflow/.local/lib/python3.12/site-packages/snowflake/connector/vendored/urllib3/util/wait.py", line 43, in _retry_on_intr
    return fn(timeout)
           ^^^^^^^^^^^
  File "/home/airflow/.local/lib/python3.12/site-packages/snowflake/connector/vendored/urllib3/util/wait.py", line 104, in do_poll
    return poll_obj.poll(t)
           ^^^^^^^^^^^^^^^^
  File "/home/airflow/.local/lib/python3.12/site-packages/airflow/models/taskinstance.py", line 2613, in signal_handler
    raise AirflowTaskTerminated("Task received SIGTERM signal")
airflow.exceptions.AirflowTaskTerminated: Task received SIGTERM signal
[2025-09-30T00:22:52.020+0000] {taskinstance.py:1206} INFO - Marking task as UP_FOR_RETRY. dag_id=ml_forecast_stock_robust, task_id=run_forecast, run_id=scheduled__2025-09-29T00:00:00+00:00, execution_date=20250929T000000, start_date=20250930T001349, end_date=20250930T002252
[2025-09-30T00:22:52.053+0000] {process_utils.py:80} INFO - Process psutil.Process(pid=40030, status='terminated', exitcode=2, started='00:13:49') (40030) terminated with exit code 2
