[2025-09-14T22:37:36.264+0000] {local_task_job_runner.py:120} INFO - ::group::Pre task execution logs
[2025-09-14T22:37:36.275+0000] {taskinstance.py:2076} INFO - Dependencies all met for dep_context=non-requeueable deps ti=<TaskInstance: sf_smoke_test.try_connect manual__2025-09-14T22:37:34.728904+00:00 [queued]>
[2025-09-14T22:37:36.278+0000] {taskinstance.py:2076} INFO - Dependencies all met for dep_context=requeueable deps ti=<TaskInstance: sf_smoke_test.try_connect manual__2025-09-14T22:37:34.728904+00:00 [queued]>
[2025-09-14T22:37:36.278+0000] {taskinstance.py:2306} INFO - Starting attempt 1 of 1
[2025-09-14T22:37:36.283+0000] {taskinstance.py:2330} INFO - Executing <Task(PythonOperator): try_connect> on 2025-09-14 22:37:34.728904+00:00
[2025-09-14T22:37:36.286+0000] {warnings.py:112} WARNING - /home/***/.local/lib/python3.12/site-packages/***/task/task_runner/standard_task_runner.py:62: DeprecationWarning: This process (pid=3746) is multi-threaded, use of fork() may lead to deadlocks in the child.
  pid = os.fork()

[2025-09-14T22:37:36.287+0000] {standard_task_runner.py:64} INFO - Started process 3748 to run task
[2025-09-14T22:37:36.287+0000] {standard_task_runner.py:90} INFO - Running: ['***', 'tasks', 'run', 'sf_smoke_test', 'try_connect', 'manual__2025-09-14T22:37:34.728904+00:00', '--job-id', '28', '--raw', '--subdir', 'DAGS_FOLDER/smoke.py', '--cfg-path', '/tmp/tmpowqhrv0u']
[2025-09-14T22:37:36.288+0000] {standard_task_runner.py:91} INFO - Job 28: Subtask try_connect
[2025-09-14T22:37:36.309+0000] {task_command.py:426} INFO - Running <TaskInstance: sf_smoke_test.try_connect manual__2025-09-14T22:37:34.728904+00:00 [running]> on host 11e1994bdecf
[2025-09-14T22:37:36.347+0000] {taskinstance.py:2648} INFO - Exporting env vars: AIRFLOW_CTX_DAG_OWNER='***' AIRFLOW_CTX_DAG_ID='sf_smoke_test' AIRFLOW_CTX_TASK_ID='try_connect' AIRFLOW_CTX_EXECUTION_DATE='2025-09-14T22:37:34.728904+00:00' AIRFLOW_CTX_TRY_NUMBER='1' AIRFLOW_CTX_DAG_RUN_ID='manual__2025-09-14T22:37:34.728904+00:00'
[2025-09-14T22:37:36.348+0000] {taskinstance.py:430} INFO - ::endgroup::
[2025-09-14T22:37:36.354+0000] {base.py:84} INFO - Using connection ID 'snowflake_default' for task execution.
[2025-09-14T22:37:36.355+0000] {connection.py:408} INFO - Snowflake Connector for Python Version: 3.11.0, Python Version: 3.12.4, Platform: Linux-6.10.14-linuxkit-aarch64-with-glibc2.36
[2025-09-14T22:37:36.356+0000] {connection.py:1258} INFO - This connection is in OCSP Fail Open Mode. TLS Certificates would be checked for validity and revocation status. Any other Certificate Revocation related exceptions or OCSP Responder failures would be disregarded in favor of connectivity.
[2025-09-14T22:37:37.151+0000] {taskinstance.py:441} INFO - ::group::Post task execution logs
[2025-09-14T22:37:37.152+0000] {taskinstance.py:2905} ERROR - Task failed with exception
Traceback (most recent call last):
  File "/home/airflow/.local/lib/python3.12/site-packages/airflow/models/taskinstance.py", line 465, in _execute_task
    result = _execute_callable(context=context, **execute_callable_kwargs)
             ^^^^^^^^^^^^^^^^^^^^^^^^^^^^^^^^^^^^^^^^^^^^^^^^^^^^^^^^^^^^^
  File "/home/airflow/.local/lib/python3.12/site-packages/airflow/models/taskinstance.py", line 432, in _execute_callable
    return execute_callable(context=context, **execute_callable_kwargs)
           ^^^^^^^^^^^^^^^^^^^^^^^^^^^^^^^^^^^^^^^^^^^^^^^^^^^^^^^^^^^^
  File "/home/airflow/.local/lib/python3.12/site-packages/airflow/models/baseoperator.py", line 401, in wrapper
    return func(self, *args, **kwargs)
           ^^^^^^^^^^^^^^^^^^^^^^^^^^^
  File "/home/airflow/.local/lib/python3.12/site-packages/airflow/operators/python.py", line 235, in execute
    return_value = self.execute_callable()
                   ^^^^^^^^^^^^^^^^^^^^^^^
  File "/home/airflow/.local/lib/python3.12/site-packages/airflow/operators/python.py", line 252, in execute_callable
    return self.python_callable(*self.op_args, **self.op_kwargs)
           ^^^^^^^^^^^^^^^^^^^^^^^^^^^^^^^^^^^^^^^^^^^^^^^^^^^^^
  File "/opt/airflow/dags/smoke.py", line 8, in sf_smoke_test
    with hook.get_conn() as conn:
         ^^^^^^^^^^^^^^^
  File "/home/airflow/.local/lib/python3.12/site-packages/airflow/providers/snowflake/hooks/snowflake.py", line 300, in get_conn
    conn = connector.connect(**conn_config)
           ^^^^^^^^^^^^^^^^^^^^^^^^^^^^^^^^
  File "/home/airflow/.local/lib/python3.12/site-packages/snowflake/connector/__init__.py", line 55, in Connect
    return SnowflakeConnection(**kwargs)
           ^^^^^^^^^^^^^^^^^^^^^^^^^^^^^
  File "/home/airflow/.local/lib/python3.12/site-packages/snowflake/connector/connection.py", line 451, in __init__
    self.connect(**kwargs)
  File "/home/airflow/.local/lib/python3.12/site-packages/snowflake/connector/connection.py", line 756, in connect
    self.__open_connection()
  File "/home/airflow/.local/lib/python3.12/site-packages/snowflake/connector/connection.py", line 1084, in __open_connection
    self.authenticate_with_retry(self.auth_class)
  File "/home/airflow/.local/lib/python3.12/site-packages/snowflake/connector/connection.py", line 1364, in authenticate_with_retry
    self._authenticate(auth_instance)
  File "/home/airflow/.local/lib/python3.12/site-packages/snowflake/connector/connection.py", line 1392, in _authenticate
    auth.authenticate(
  File "/home/airflow/.local/lib/python3.12/site-packages/snowflake/connector/auth/_auth.py", line 401, in authenticate
    Error.errorhandler_wrapper(
  File "/home/airflow/.local/lib/python3.12/site-packages/snowflake/connector/errors.py", line 290, in errorhandler_wrapper
    handed_over = Error.hand_to_other_handler(
                  ^^^^^^^^^^^^^^^^^^^^^^^^^^^^
  File "/home/airflow/.local/lib/python3.12/site-packages/snowflake/connector/errors.py", line 348, in hand_to_other_handler
    connection.errorhandler(connection, cursor, error_class, error_value)
  File "/home/airflow/.local/lib/python3.12/site-packages/snowflake/connector/errors.py", line 221, in default_errorhandler
    raise error_class(
snowflake.connector.errors.DatabaseError: 250001 (08001): None: Failed to connect to DB: SFEDU02-LVB17920.snowflakecomputing.com:443. Fail : Network policy is required.
[2025-09-14T22:37:37.161+0000] {taskinstance.py:1206} INFO - Marking task as FAILED. dag_id=sf_smoke_test, task_id=try_connect, run_id=manual__2025-09-14T22:37:34.728904+00:00, execution_date=20250914T223734, start_date=20250914T223736, end_date=20250914T223737
[2025-09-14T22:37:37.170+0000] {standard_task_runner.py:110} ERROR - Failed to execute job 28 for task try_connect (250001 (08001): None: Failed to connect to DB: SFEDU02-LVB17920.snowflakecomputing.com:443. Fail : Network policy is required.; 3748)
[2025-09-14T22:37:37.177+0000] {local_task_job_runner.py:243} INFO - Task exited with return code 1
[2025-09-14T22:37:37.184+0000] {taskinstance.py:3503} INFO - 0 downstream tasks scheduled from follow-on schedule check
[2025-09-14T22:37:37.185+0000] {local_task_job_runner.py:222} INFO - ::endgroup::
