[2025-09-13T22:50:49.631+0000] {local_task_job_runner.py:120} INFO - ::group::Pre task execution logs
[2025-09-13T22:50:49.641+0000] {taskinstance.py:2076} INFO - Dependencies all met for dep_context=non-requeueable deps ti=<TaskInstance: etl_yfinance_stock.fetch_and_upsert manual__2025-09-13T22:50:48.330613+00:00 [queued]>
[2025-09-13T22:50:49.643+0000] {taskinstance.py:2076} INFO - Dependencies all met for dep_context=requeueable deps ti=<TaskInstance: etl_yfinance_stock.fetch_and_upsert manual__2025-09-13T22:50:48.330613+00:00 [queued]>
[2025-09-13T22:50:49.643+0000] {taskinstance.py:2306} INFO - Starting attempt 1 of 2
[2025-09-13T22:50:49.647+0000] {taskinstance.py:2330} INFO - Executing <Task(PythonOperator): fetch_and_upsert> on 2025-09-13 22:50:48.330613+00:00
[2025-09-13T22:50:49.652+0000] {warnings.py:112} WARNING - /home/***/.local/lib/python3.12/site-packages/***/task/task_runner/standard_task_runner.py:62: DeprecationWarning: This process (pid=1032) is multi-threaded, use of fork() may lead to deadlocks in the child.
  pid = os.fork()

[2025-09-13T22:50:49.653+0000] {standard_task_runner.py:64} INFO - Started process 1034 to run task
[2025-09-13T22:50:49.653+0000] {standard_task_runner.py:90} INFO - Running: ['***', 'tasks', 'run', 'etl_yfinance_stock', 'fetch_and_upsert', 'manual__2025-09-13T22:50:48.330613+00:00', '--job-id', '11', '--raw', '--subdir', 'DAGS_FOLDER/etl_yfinance_stock.py', '--cfg-path', '/tmp/tmpwd1qt0oj']
[2025-09-13T22:50:49.653+0000] {standard_task_runner.py:91} INFO - Job 11: Subtask fetch_and_upsert
[2025-09-13T22:50:49.670+0000] {task_command.py:426} INFO - Running <TaskInstance: etl_yfinance_stock.fetch_and_upsert manual__2025-09-13T22:50:48.330613+00:00 [running]> on host 11e1994bdecf
[2025-09-13T22:50:49.806+0000] {taskinstance.py:2648} INFO - Exporting env vars: AIRFLOW_CTX_DAG_OWNER='dingyuyao' AIRFLOW_CTX_DAG_ID='etl_yfinance_stock' AIRFLOW_CTX_TASK_ID='fetch_and_upsert' AIRFLOW_CTX_EXECUTION_DATE='2025-09-13T22:50:48.330613+00:00' AIRFLOW_CTX_TRY_NUMBER='1' AIRFLOW_CTX_DAG_RUN_ID='manual__2025-09-13T22:50:48.330613+00:00'
[2025-09-13T22:50:49.806+0000] {taskinstance.py:430} INFO - ::endgroup::
[2025-09-13T22:50:49.809+0000] {warnings.py:112} WARNING - /opt/***/dags/etl_yfinance_stock.py:36: FutureWarning: YF.download() has changed argument auto_adjust default to True
  df = yf.download(symbol, start = start_date.isoformat(), end = end_date.isoformat(), progress = False)

[2025-09-13T22:50:50.317+0000] {warnings.py:112} WARNING - /opt/***/dags/etl_yfinance_stock.py:36: FutureWarning: YF.download() has changed argument auto_adjust default to True
  df = yf.download(symbol, start = start_date.isoformat(), end = end_date.isoformat(), progress = False)

[2025-09-13T22:50:50.606+0000] {base.py:84} INFO - Using connection ID 'snowflake_default' for task execution.
[2025-09-13T22:50:50.606+0000] {connection.py:408} INFO - Snowflake Connector for Python Version: 3.11.0, Python Version: 3.12.4, Platform: Linux-6.10.14-linuxkit-aarch64-with-glibc2.36
[2025-09-13T22:50:50.607+0000] {connection.py:1258} INFO - This connection is in OCSP Fail Open Mode. TLS Certificates would be checked for validity and revocation status. Any other Certificate Revocation related exceptions or OCSP Responder failures would be disregarded in favor of connectivity.
[2025-09-13T22:50:51.103+0000] {taskinstance.py:441} INFO - ::group::Post task execution logs
[2025-09-13T22:50:51.104+0000] {taskinstance.py:2905} ERROR - Task failed with exception
Traceback (most recent call last):
  File "/home/airflow/.local/lib/python3.12/site-packages/airflow/models/taskinstance.py", line 465, in _execute_task
    result = _execute_callable(context=context, **execute_callable_kwargs)
             ^^^^^^^^^^^^^^^^^^^^^^^^^^^^^^^^^^^^^^^^^^^^^^^^^^^^^^^^^^^^^
  File "/home/airflow/.local/lib/python3.12/site-packages/airflow/models/taskinstance.py", line 432, in _execute_callable
    return execute_callable(context=context, **execute_callable_kwargs)
           ^^^^^^^^^^^^^^^^^^^^^^^^^^^^^^^^^^^^^^^^^^^^^^^^^^^^^^^^^^^^
  File "/home/airflow/.local/lib/python3.12/site-packages/airflow/models/baseoperator.py", line 401, in wrapper
    return func(self, *args, **kwargs)
           ^^^^^^^^^^^^^^^^^^^^^^^^^^^
  File "/home/airflow/.local/lib/python3.12/site-packages/airflow/operators/python.py", line 235, in execute
    return_value = self.execute_callable()
                   ^^^^^^^^^^^^^^^^^^^^^^^
  File "/home/airflow/.local/lib/python3.12/site-packages/airflow/operators/python.py", line 252, in execute_callable
    return self.python_callable(*self.op_args, **self.op_kwargs)
           ^^^^^^^^^^^^^^^^^^^^^^^^^^^^^^^^^^^^^^^^^^^^^^^^^^^^^
  File "/opt/airflow/dags/etl_yfinance_stock.py", line 63, in fetch_and_upsert
    conn = hook.get_conn()
           ^^^^^^^^^^^^^^^
  File "/home/airflow/.local/lib/python3.12/site-packages/airflow/providers/snowflake/hooks/snowflake.py", line 300, in get_conn
    conn = connector.connect(**conn_config)
           ^^^^^^^^^^^^^^^^^^^^^^^^^^^^^^^^
  File "/home/airflow/.local/lib/python3.12/site-packages/snowflake/connector/__init__.py", line 55, in Connect
    return SnowflakeConnection(**kwargs)
           ^^^^^^^^^^^^^^^^^^^^^^^^^^^^^
  File "/home/airflow/.local/lib/python3.12/site-packages/snowflake/connector/connection.py", line 451, in __init__
    self.connect(**kwargs)
  File "/home/airflow/.local/lib/python3.12/site-packages/snowflake/connector/connection.py", line 756, in connect
    self.__open_connection()
  File "/home/airflow/.local/lib/python3.12/site-packages/snowflake/connector/connection.py", line 1084, in __open_connection
    self.authenticate_with_retry(self.auth_class)
  File "/home/airflow/.local/lib/python3.12/site-packages/snowflake/connector/connection.py", line 1364, in authenticate_with_retry
    self._authenticate(auth_instance)
  File "/home/airflow/.local/lib/python3.12/site-packages/snowflake/connector/connection.py", line 1392, in _authenticate
    auth.authenticate(
  File "/home/airflow/.local/lib/python3.12/site-packages/snowflake/connector/auth/_auth.py", line 401, in authenticate
    Error.errorhandler_wrapper(
  File "/home/airflow/.local/lib/python3.12/site-packages/snowflake/connector/errors.py", line 290, in errorhandler_wrapper
    handed_over = Error.hand_to_other_handler(
                  ^^^^^^^^^^^^^^^^^^^^^^^^^^^^
  File "/home/airflow/.local/lib/python3.12/site-packages/snowflake/connector/errors.py", line 348, in hand_to_other_handler
    connection.errorhandler(connection, cursor, error_class, error_value)
  File "/home/airflow/.local/lib/python3.12/site-packages/snowflake/connector/errors.py", line 221, in default_errorhandler
    raise error_class(
snowflake.connector.errors.DatabaseError: 250001 (08001): None: Failed to connect to DB: SFEDU02-LVB17920.snowflakecomputing.com:443. Failed to authenticate: MFA authentication is required, but none of your current MFA methods are supported for programmatic authentication.
[2025-09-13T22:50:51.112+0000] {taskinstance.py:1206} INFO - Marking task as UP_FOR_RETRY. dag_id=etl_yfinance_stock, task_id=fetch_and_upsert, run_id=manual__2025-09-13T22:50:48.330613+00:00, execution_date=20250913T225048, start_date=20250913T225049, end_date=20250913T225051
[2025-09-13T22:50:51.121+0000] {standard_task_runner.py:110} ERROR - Failed to execute job 11 for task fetch_and_upsert (250001 (08001): None: Failed to connect to DB: SFEDU02-LVB17920.snowflakecomputing.com:443. Failed to authenticate: MFA authentication is required, but none of your current MFA methods are supported for programmatic authentication.; 1034)
[2025-09-13T22:50:51.167+0000] {local_task_job_runner.py:243} INFO - Task exited with return code 1
[2025-09-13T22:50:51.177+0000] {taskinstance.py:3503} INFO - 0 downstream tasks scheduled from follow-on schedule check
[2025-09-13T22:50:51.177+0000] {local_task_job_runner.py:222} INFO - ::endgroup::
