[2025-09-13T15:32:37.983+0000] {local_task_job_runner.py:120} INFO - ::group::Pre task execution logs
[2025-09-13T15:32:37.995+0000] {taskinstance.py:2076} INFO - Dependencies all met for dep_context=non-requeueable deps ti=<TaskInstance: etl_yfinance_stock.fetch_and_upsert scheduled__2025-09-12T00:00:00+00:00 [queued]>
[2025-09-13T15:32:37.999+0000] {taskinstance.py:2076} INFO - Dependencies all met for dep_context=requeueable deps ti=<TaskInstance: etl_yfinance_stock.fetch_and_upsert scheduled__2025-09-12T00:00:00+00:00 [queued]>
[2025-09-13T15:32:37.999+0000] {taskinstance.py:2306} INFO - Starting attempt 2 of 2
[2025-09-13T15:32:38.008+0000] {taskinstance.py:2330} INFO - Executing <Task(PythonOperator): fetch_and_upsert> on 2025-09-12 00:00:00+00:00
[2025-09-13T15:32:38.015+0000] {warnings.py:112} WARNING - /home/***/.local/lib/python3.12/site-packages/***/task/task_runner/standard_task_runner.py:62: DeprecationWarning: This process (pid=328) is multi-threaded, use of fork() may lead to deadlocks in the child.
  pid = os.fork()

[2025-09-13T15:32:38.017+0000] {standard_task_runner.py:64} INFO - Started process 333 to run task
[2025-09-13T15:32:38.018+0000] {standard_task_runner.py:90} INFO - Running: ['***', 'tasks', 'run', 'etl_yfinance_stock', 'fetch_and_upsert', 'scheduled__2025-09-12T00:00:00+00:00', '--job-id', '8', '--raw', '--subdir', 'DAGS_FOLDER/etl_yfinance_stock.py', '--cfg-path', '/tmp/tmp8xt4ja4o']
[2025-09-13T15:32:38.019+0000] {standard_task_runner.py:91} INFO - Job 8: Subtask fetch_and_upsert
[2025-09-13T15:32:38.056+0000] {task_command.py:426} INFO - Running <TaskInstance: etl_yfinance_stock.fetch_and_upsert scheduled__2025-09-12T00:00:00+00:00 [running]> on host 11e1994bdecf
[2025-09-13T15:32:38.418+0000] {taskinstance.py:2648} INFO - Exporting env vars: AIRFLOW_CTX_DAG_OWNER='dingyuyao' AIRFLOW_CTX_DAG_ID='etl_yfinance_stock' AIRFLOW_CTX_TASK_ID='fetch_and_upsert' AIRFLOW_CTX_EXECUTION_DATE='2025-09-12T00:00:00+00:00' AIRFLOW_CTX_TRY_NUMBER='2' AIRFLOW_CTX_DAG_RUN_ID='scheduled__2025-09-12T00:00:00+00:00'
[2025-09-13T15:32:38.419+0000] {taskinstance.py:430} INFO - ::endgroup::
[2025-09-13T15:32:38.425+0000] {warnings.py:112} WARNING - /opt/***/dags/etl_yfinance_stock.py:36: FutureWarning: YF.download() has changed argument auto_adjust default to True
  df = yf.download(symbol, start = start_date.isoformat(), end = end_date.isoformat(), progress = False)

[2025-09-13T15:32:38.971+0000] {warnings.py:112} WARNING - /opt/***/dags/etl_yfinance_stock.py:36: FutureWarning: YF.download() has changed argument auto_adjust default to True
  df = yf.download(symbol, start = start_date.isoformat(), end = end_date.isoformat(), progress = False)

[2025-09-13T15:32:39.252+0000] {taskinstance.py:441} INFO - ::group::Post task execution logs
[2025-09-13T15:32:39.257+0000] {taskinstance.py:2905} ERROR - Task failed with exception
Traceback (most recent call last):
  File "/home/airflow/.local/lib/python3.12/site-packages/airflow/models/taskinstance.py", line 465, in _execute_task
    result = _execute_callable(context=context, **execute_callable_kwargs)
             ^^^^^^^^^^^^^^^^^^^^^^^^^^^^^^^^^^^^^^^^^^^^^^^^^^^^^^^^^^^^^
  File "/home/airflow/.local/lib/python3.12/site-packages/airflow/models/taskinstance.py", line 432, in _execute_callable
    return execute_callable(context=context, **execute_callable_kwargs)
           ^^^^^^^^^^^^^^^^^^^^^^^^^^^^^^^^^^^^^^^^^^^^^^^^^^^^^^^^^^^^
  File "/home/airflow/.local/lib/python3.12/site-packages/airflow/models/baseoperator.py", line 401, in wrapper
    return func(self, *args, **kwargs)
           ^^^^^^^^^^^^^^^^^^^^^^^^^^^
  File "/home/airflow/.local/lib/python3.12/site-packages/airflow/operators/python.py", line 235, in execute
    return_value = self.execute_callable()
                   ^^^^^^^^^^^^^^^^^^^^^^^
  File "/home/airflow/.local/lib/python3.12/site-packages/airflow/operators/python.py", line 252, in execute_callable
    return self.python_callable(*self.op_args, **self.op_kwargs)
           ^^^^^^^^^^^^^^^^^^^^^^^^^^^^^^^^^^^^^^^^^^^^^^^^^^^^^
  File "/opt/airflow/dags/etl_yfinance_stock.py", line 63, in fetch_and_upsert
    conn = hook.get_conn()
           ^^^^^^^^^^^^^^^
  File "/home/airflow/.local/lib/python3.12/site-packages/airflow/providers/snowflake/hooks/snowflake.py", line 299, in get_conn
    conn_config = self._get_conn_params
                  ^^^^^^^^^^^^^^^^^^^^^
  File "/usr/local/lib/python3.12/functools.py", line 995, in __get__
    val = self.func(instance)
          ^^^^^^^^^^^^^^^^^^^
  File "/home/airflow/.local/lib/python3.12/site-packages/airflow/providers/snowflake/hooks/snowflake.py", line 192, in _get_conn_params
    conn = self.get_connection(self.snowflake_conn_id)  # type: ignore[attr-defined]
           ^^^^^^^^^^^^^^^^^^^^^^^^^^^^^^^^^^^^^^^^^^^
  File "/home/airflow/.local/lib/python3.12/site-packages/airflow/hooks/base.py", line 83, in get_connection
    conn = Connection.get_connection_from_secrets(conn_id)
           ^^^^^^^^^^^^^^^^^^^^^^^^^^^^^^^^^^^^^^^^^^^^^^^
  File "/home/airflow/.local/lib/python3.12/site-packages/airflow/models/connection.py", line 519, in get_connection_from_secrets
    raise AirflowNotFoundException(f"The conn_id `{conn_id}` isn't defined")
airflow.exceptions.AirflowNotFoundException: The conn_id `snowflake_default` isn't defined
[2025-09-13T15:32:39.261+0000] {taskinstance.py:1206} INFO - Marking task as FAILED. dag_id=etl_yfinance_stock, task_id=fetch_and_upsert, run_id=scheduled__2025-09-12T00:00:00+00:00, execution_date=20250912T000000, start_date=20250913T153237, end_date=20250913T153239
[2025-09-13T15:32:39.270+0000] {standard_task_runner.py:110} ERROR - Failed to execute job 8 for task fetch_and_upsert (The conn_id `snowflake_default` isn't defined; 333)
[2025-09-13T15:32:39.317+0000] {local_task_job_runner.py:243} INFO - Task exited with return code 1
[2025-09-13T15:32:39.327+0000] {taskinstance.py:3503} INFO - 0 downstream tasks scheduled from follow-on schedule check
[2025-09-13T15:32:39.327+0000] {local_task_job_runner.py:222} INFO - ::endgroup::
